Workbook

Sheet ReadMe
A1: Brookfield Wealth Solutions (BNT) — quarterly + annual engine
A3: Units: US$ millions as printed. Blue = value as printed in the source; black bold = live formula;
A4: CHECK rows verify identities cell-by-cell (OK / FAIL / n/a where a period is not published).
A5: Checks tab = master count of failing checks (must read 0).
A7: Sources: BNT 20-F FY2025 (three-year statements; FY2023 face balance sheet not printed — cells blank,
A8: boundary logged) · BWS supplementals Q4-2025 + Q1-2026 (quarterly series began 1Q25; 4Q24 comparative).
A9: All documents sha-tracked in acquisition/manifest.csv; extraction in extract/cross-section/bnt_engine_raw.csv
A10: (481 rows, anchor-quoted). Regenerate: python3 tools/build_platform_engines.py bnt
A12: Boundary: no quarterly series exists before 1Q25 (BNT is a foreign private issuer, 20-F/6-K cadence).
A13: The BN/BNT merger (approved 2026-07-16) is expected to end standalone reporting.

Sheet Engine-FY
B1: FY2023 | C1: FY2024 | D1: FY2025
A3: ① MONEY IN — annuity sales and net premiums (US$ millions)
A4: Retail annuity sales — fixed index | B4: 2206 | C4: 5522 | D4: 9032
A5: Retail annuity sales — fixed rate | B5: 3938 | C5: 5132 | D5: 6236
A6: Retail annuity sales — variable/other | B6: 63 | C6: 372 | D6: 393
A7: Retail annuity sales (printed) | B7: 6207 | C7: 11026 | D7: 15661
A8: CHECK: retail sales foot | B8: =IF(OR(B4+B5+B6="",B7=""),"n/a",IF(ABS(B4+B5+B6-B7)<=2,"OK","FAIL")) | C8: =IF(OR(C4+C5+C6="",C7=""),"n/a",IF(ABS(C4+C5+C6-C7)<=2,"OK","FAIL")) | D8: =IF(OR(D4+D5+D6="",D7=""),"n/a",IF(ABS(D4+D5+D6-D7)<=2,"OK","FAIL"))
A9: Institutional — PRT | B9: 1469 | C9: 4814 | D9: 1879
A10: Institutional — funding agreements | B10: 0 | C10: 0 | D10: 2289
A11: Institutional annuity sales (printed) | B11: 1469 | C11: 4814 | D11: 4168
A12: CHECK: institutional sales foot | B12: =IF(OR(B9+B10="",B11=""),"n/a",IF(ABS(B9+B10-B11)<=2,"OK","FAIL")) | C12: =IF(OR(C9+C10="",C11=""),"n/a",IF(ABS(C9+C10-C11)<=2,"OK","FAIL")) | D12: =IF(OR(D9+D10="",D11=""),"n/a",IF(ABS(D9+D10-D11)<=2,"OK","FAIL"))
A13: TOTAL GROSS ANNUITY SALES (printed) | B13: 7676 | C13: 15840 | D13: 19829
A14: CHECK: retail + institutional = total sales | B14: =IF(OR(B7+B11="",B13=""),"n/a",IF(ABS(B7+B11-B13)<=2,"OK","FAIL")) | C14: =IF(OR(C7+C11="",C13=""),"n/a",IF(ABS(C7+C11-C13)<=2,"OK","FAIL")) | D14: =IF(OR(D7+D11="",D13=""),"n/a",IF(ABS(D7+D11-D13)<=2,"OK","FAIL"))
A15: Net premiums — annuities | B15: 1469 | C15: 4813 | D15: 1714
A16: Net premiums — P&C | B16: 2148 | C16: 2943 | D16: 2396
A17: Net premiums — whole life & others | B17: 520 | C17: 511 | D17: 377
A18: NET PREMIUMS (printed) | B18: 4137 | C18: 8267 | D18: 4487
A19: CHECK: net premiums by product foot | B19: =IF(OR(B15+B16+B17="",B18=""),"n/a",IF(ABS(B15+B16+B17-B18)<=2,"OK","FAIL")) | C19: =IF(OR(C15+C16+C17="",C18=""),"n/a",IF(ABS(C15+C16+C17-C18)<=2,"OK","FAIL")) | D19: =IF(OR(D15+D16+D17="",D18=""),"n/a",IF(ABS(D15+D16+D17-D18)<=2,"OK","FAIL"))
A20: Policyholders' account deposits (cash flow) | B20: 4920 | C20: 10865 | D20: 17650
A21: Policyholders' account withdrawals (cash flow) | B21: -2281 | C21: -8753 | D21: -10299
A23: ② REVENUES (US GAAP)
A24: Net premiums | B24: 4137 | C24: 8267 | D24: 4487
A25: Other policy revenue | B25: 413 | C25: 781 | D25: 790
A26: Net investment income | B26: 1809 | C26: 4264 | D26: 5819
A27: Investment related gains | B27: 425 | C27: 369 | D27: 485
A28: Net investment results — reinsurance funds withheld | B28: 128 | C28: 422 | D28: 54
A29: TOTAL REVENUES (printed) | B29: 6912 | C29: 14103 | D29: 11635
A30: CHECK: revenue lines foot | B30: =IF(OR(B24+B25+B26+B27+B28="",B29=""),"n/a",IF(ABS(B24+B25+B26+B27+B28-B29)<=2,"OK","FAIL")) | C30: =IF(OR(C24+C25+C26+C27+C28="",C29=""),"n/a",IF(ABS(C24+C25+C26+C27+C28-C29)<=2,"OK","FAIL")) | D30: =IF(OR(D24+D25+D26+D27+D28="",D29=""),"n/a",IF(ABS(D24+D25+D26+D27+D28-D29)<=2,"OK","FAIL"))
A32: ③ BENEFITS AND EXPENSES (stored signed as printed — parentheses negative)
A33: Policyholder benefits and claims incurred | B33: -3939 | C33: -8162 | D33: -4489
A34: Interest sensitive contract benefits | B34: -687 | C34: -1874 | D34: -2072
A35: Amortization of DAC / DSI / VOBA | B35: -632 | C35: -1237 | D35: -1418
A36: Operating expenses | B36: -777 | C36: -1356 | D36: -1361
A37: Interest expense | B37: -249 | C37: -362 | D37: -379
A38: Other reinsurance expenses | B38: -21 | C38: -26 | D38: -5
A39: Change in FV — insurance & embedded derivatives | B39: 41 | C39: 234 | D39: -219
A40: Change in FV — market risk benefits | B40: 166 | C40: -107 | D40: -725
A41: TOTAL BENEFITS AND EXPENSES (printed) | B41: -6098 | C41: -12890 | D41: -10668
A42: CHECK: expense lines foot | B42: =IF(OR(B33+B34+B35+B36+B37+B38+B39+B40="",B41=""),"n/a",IF(ABS(B33+B34+B35+B36+B37+B38+B39+B40-B41)<=2,"OK","FAIL")) | C42: =IF(OR(C33+C34+C35+C36+C37+C38+C39+C40="",C41=""),"n/a",IF(ABS(C33+C34+C35+C36+C37+C38+C39+C40-C41)<=2,"OK","FAIL")) | D42: =IF(OR(D33+D34+D35+D36+D37+D38+D39+D40="",D41=""),"n/a",IF(ABS(D33+D34+D35+D36+D37+D38+D39+D40-D41)<=2,"OK","FAIL"))
A44: ④ NET INCOME
...

Sheet Engine
B1: 4Q24 | C1: 1Q25 | D1: 2Q25 | E1: 3Q25 | F1: 4Q25 | G1: 1Q26
A3: ① THE SPREAD ENGINE — DOE basis (US$ millions)
A4: DOE net investment income | B4: 1457 | C4: 1546 | D4: 1582 | E4: 1610 | F4: 1680 | G4: 1686
A5: DOE cost of funds | B5: -827 | C5: -904 | D5: -996 | E5: -987 | F5: -1002 | G5: -1028
A6: GROSS SPREAD (printed) | B6: 630 | C6: 642 | D6: 586 | E6: 623 | F6: 678 | G6: 658
A7: CHECK: NII + cost of funds = gross spread | B7: =IF(OR(B4+B5="",B6=""),"n/a",IF(ABS(B4+B5-B6)<=2,"OK","FAIL")) | C7: =IF(OR(C4+C5="",C6=""),"n/a",IF(ABS(C4+C5-C6)<=2,"OK","FAIL")) | D7: =IF(OR(D4+D5="",D6=""),"n/a",IF(ABS(D4+D5-D6)<=2,"OK","FAIL")) | E7: =IF(OR(E4+E5="",E6=""),"n/a",IF(ABS(E4+E5-E6)<=2,"OK","FAIL")) | F7: =IF(OR(F4+F5="",F6=""),"n/a",IF(ABS(F4+F5-F6)<=2,"OK","FAIL")) | G7: =IF(OR(G4+G5="",G6=""),"n/a",IF(ABS(G4+G5-G6)<=2,"OK","FAIL"))
A8: interest expense | B8: -96 | C8: -80 | D8: -82 | E8: -90 | F8: -92 | G8: -92
A9: operating expenses and other | B9: -107 | C9: -125 | D9: -106 | E9: -106 | F9: -149 | G9: -128
A10: DISTRIBUTABLE OPERATING EARNINGS | B10: 427 | C10: 437 | D10: 398 | E10: 427 | F10: 437 | G10: 438
A11: CHECK: gross spread − interest − opex&other = DOE | B11: =IF(OR(B6+B8+B9="",B10=""),"n/a",IF(ABS(B6+B8+B9-B10)<=2,"OK","FAIL")) | C11: =IF(OR(C6+C8+C9="",C10=""),"n/a",IF(ABS(C6+C8+C9-C10)<=2,"OK","FAIL")) | D11: =IF(OR(D6+D8+D9="",D10=""),"n/a",IF(ABS(D6+D8+D9-D10)<=2,"OK","FAIL")) | E11: =IF(OR(E6+E8+E9="",E10=""),"n/a",IF(ABS(E6+E8+E9-E10)<=2,"OK","FAIL")) | F11: =IF(OR(F6+F8+F9="",F10=""),"n/a",IF(ABS(F6+F8+F9-F10)<=2,"OK","FAIL")) | G11: =IF(OR(G6+G8+G9="",G10=""),"n/a",IF(ABS(G6+G8+G9-G10)<=2,"OK","FAIL"))
A12: income tax (segment-pretax view) | B12: -89 | C12: -96 | D12: -87 | E12: -94 | F12: -96 | G12: -96
A13: GAAP NET INCOME (LOSS) | B13: 576 | C13: -282 | D13: 516 | E13: 608 | F13: 21 | G13: -602
A14: GAAP vs DOE divergence: 1Q25 −282 vs +437 · 1Q26 −602 vs +438 — the sector pattern, quarterly.
A15: pretax DOE — annuities | B15: 416 | C15: 422 | D15: 410 | E15: 399 | F15: 432 | G15: 456
A16: pretax DOE — P&C | B16: 102 | C16: 118 | D16: 65 | E16: 113 | F16: 103 | G16: 124
A17: pretax DOE — life insurance | B17: 32 | C17: 32 | D17: 40 | E17: 37 | F17: 44 | G17: 20
A18: pretax DOE — corporate & other | B18: -34 | C18: -39 | D18: -30 | E18: -28 | F18: -46 | G18: -66
A19: Total pretax DOE (printed) | B19: 516 | C19: 533 | D19: 485 | E19: 521 | F19: 533 | G19: 534
A20: CHECK: pretax DOE + tax = DOE | B20: =IF(OR(B19+B12="",B10=""),"n/a",IF(ABS(B19+B12-B10)<=2,"OK","FAIL")) | C20: =IF(OR(C19+C12="",C10=""),"n/a",IF(ABS(C19+C12-C10)<=2,"OK","FAIL")) | D20: =IF(OR(D19+D12="",D10=""),"n/a",IF(ABS(D19+D12-D10)<=2,"OK","FAIL")) | E20: =IF(OR(E19+E12="",E10=""),"n/a",IF(ABS(E19+E12-E10)<=2,"OK","FAIL")) | F20: =IF(OR(F19+F12="",F10=""),"n/a",IF(ABS(F19+F12-F10)<=2,"OK","FAIL")) | G20: =IF(OR(G19+G12="",G10=""),"n/a",IF(ABS(G19+G12-G10)<=2,"OK","FAIL"))
A21: CHECK: segment pretax DOE foots | B21: =IF(OR(B15+B16+B17+B18="",B19=""),"n/a",IF(ABS(B15+B16+B17+B18-B19)<=2,"OK","FAIL")) | C21: =IF(OR(C15+C16+C17+C18="",C19=""),"n/a",IF(ABS(C15+C16+C17+C18-C19)<=2,"OK","FAIL")) | D21: =IF(OR(D15+D16+D17+D18="",D19=""),"n/a",IF(ABS(D15+D16+D17+D18-D19)<=2,"OK","FAIL")) | E21: =IF(OR(E15+E16+E17+E18="",E19=""),"n/a",IF(ABS(E15+E16+E17+E18-E19)<=2,"OK","FAIL")) | F21: =IF(OR(F15+F16+F17+F18="",F19=""),"n/a",IF(ABS(F15+F16+F17+F18-F19)<=2,"OK","FAIL")) | G21: =IF(OR(G15+G16+G17+G18="",G19=""),"n/a",IF(ABS(G15+G16+G17+G18-G19)<=2,"OK","FAIL"))
A23: ② THE ANNUITY RULER — rates (printed, %)
A24: Annuity net investment income (rate) | B24: 1220 | C24: 1321 | D24: 1345 | E24: 1371 | F24: 1416 | G24: 1487
A25: Annuity cost of funds (rate) | B25: -804 | C25: -899 | D25: -935 | E25: -972 | F25: -984 | G25: -1031
A26: ANNUITY NET INVESTMENT SPREAD | B26: 416 | C26: 422 | D26: 410 | E26: 399 | F26: 432 | G26: 456
A27: Annuity average invested assets | B27: 87507 | C27: 91266 | D27: 93479 | E27: 96527 | F27: 100708 | G27: 103465
A29: ③ FLOWS — sales, outflows, net flows
A30: Retail sales — fixed index | B30: 1797 | C30: 1835 | D30: 2513 | E30: 2529 | F30: 2155 | G30: 1691
A31: Retail sales — fixed rate | B31: 918 | C31: 1049 | D31: 1031 | E31: 2128 | F31: 2028 | G31: 1385
A32: Retail sales — variable/other | B32: 16 | C32: 46 | D32: 80 | E32: 101 | F32: 166 | G32: 176
A33: Total retail sales (printed) | B33: 2731 | C33: 2930 | D33: 3624 | E33: 4758 | F33: 4349 | G33: 3252
A34: CHECK: retail foots | B34: =IF(OR(B30+B31+B32="",B33=""),"n/a",IF(ABS(B30+B31+B32-B33)<=2,"OK","FAIL")) | C34: =IF(OR(C30+C31+C32="",C33=""),"n/a",IF(ABS(C30+C31+C32-C33)<=2,"OK","FAIL")) | D34: =IF(OR(D30+D31+D32="",D33=""),"n/a",IF(ABS(D30+D31+D32-D33)<=2,"OK","FAIL")) | E34: =IF(OR(E30+E31+E32="",E33=""),"n/a",IF(ABS(E30+E31+E32-E33)<=2,"OK","FAIL")) | F34: =IF(OR(F30+F31+F32="",F33=""),"n/a",IF(ABS(F30+F31+F32-F33)<=2,"OK","FAIL")) | G34: =IF(OR(G30+G31+G32="",G33=""),"n/a",IF(ABS(G30+G31+G32-G33)<=2,"OK","FAIL"))
A35: Institutional — PRT | B35: 3241 | C35: 408 | D35: 311 | E35: 280 | F35: 880 | G35: 90
A36: Institutional — funding agreements | B36: 0 | C36: 500 | D36: 400 | E36: 0 | F36: 1389 | G36: 500
A37: Total institutional sales (printed) | B37: 3241 | C37: 908 | D37: 711 | E37: 280 | F37: 2269 | G37: 590
A38: CHECK: institutional foots | B38: =IF(OR(B35+B36="",B37=""),"n/a",IF(ABS(B35+B36-B37)<=2,"OK","FAIL")) | C38: =IF(OR(C35+C36="",C37=""),"n/a",IF(ABS(C35+C36-C37)<=2,"OK","FAIL")) | D38: =IF(OR(D35+D36="",D37=""),"n/a",IF(ABS(D35+D36-D37)<=2,"OK","FAIL")) | E38: =IF(OR(E35+E36="",E37=""),"n/a",IF(ABS(E35+E36-E37)<=2,"OK","FAIL")) | F38: =IF(OR(F35+F36="",F37=""),"n/a",IF(ABS(F35+F36-F37)<=2,"OK","FAIL")) | G38: =IF(OR(G35+G36="",G37=""),"n/a",IF(ABS(G35+G36-G37)<=2,"OK","FAIL"))
A39: TOTAL GROSS ANNUITY SALES (printed) | B39: 5972 | C39: 3838 | D39: 4335 | E39: 5038 | F39: 6618 | G39: 3842
A40: CHECK: retail + institutional = gross sales | B40: =IF(OR(B33+B37="",B39=""),"n/a",IF(ABS(B33+B37-B39)<=2,"OK","FAIL")) | C40: =IF(OR(C33+C37="",C39=""),"n/a",IF(ABS(C33+C37-C39)<=2,"OK","FAIL")) | D40: =IF(OR(D33+D37="",D39=""),"n/a",IF(ABS(D33+D37-D39)<=2,"OK","FAIL")) | E40: =IF(OR(E33+E37="",E39=""),"n/a",IF(ABS(E33+E37-E39)<=2,"OK","FAIL")) | F40: =IF(OR(F33+F37="",F39=""),"n/a",IF(ABS(F33+F37-F39)<=2,"OK","FAIL")) | G40: =IF(OR(G33+G37="",G39=""),"n/a",IF(ABS(G33+G37-G39)<=2,"OK","FAIL"))
A41: retail outflows | B41: -2246 | C41: -2158 | D41: -2475 | E41: -2816 | F41: -2763 | G41: -2730
A42: institutional outflows | B42: -150 | C42: -142 | D42: -180 | E42: -201 | F42: -221 | G42: -225
A43: Total net annuity sales (printed) | B43: 5969 | C43: 3831 | D43: 4326 | E43: 5024 | F43: 6604 | G43: 3840
...

Sheet Checks
A1: Master check — count of FAIL cells across all engine tabs (must be 0)
A2: TOTAL FAILING CHECKS | B2: =B3+B4+B5+B6
A3: chunk 1 | B3: =COUNTIF('Engine-FY'!B8,"FAIL")+COUNTIF('Engine-FY'!C8,"FAIL")+COUNTIF('Engine-FY'!D8,"FAIL")+COUNTIF('Engine-FY'!B12,"FAIL")+COUNTIF('Engine-FY'!C12,"FAIL")+COUNTIF('Engine-FY'!D12,"FAIL")+COUNTIF('Engine-FY'!B14,"FAIL")+COUNTIF('Engine-FY'!C14,"FAIL")+COUNTIF('Engine-FY'!D14,"FAIL")+COUNTIF('Engine-FY'!B19,"FAIL")+COUNTIF('Engine-FY'!C19,"FAIL")+COUNTIF('Engine-FY'!D19,"FAIL")+COUNTIF('Engine-FY'!B30,"FAIL")+COUNTIF('Engine-FY'!C30,"FAIL")+COUNTIF('Engine-FY'!D30,"FAIL")+COUNTIF('Engine-FY'!B42,"FAIL")+COUNTIF('Engine-FY'!C42,"FAIL")+COUNTIF('Engine-FY'!D42,"FAIL")+COUNTIF('Engine-FY'!B46,"FAIL")+COUNTIF('Engine-FY'!C46,"FAIL")+COUNTIF('Engine-FY'!D46,"FAIL")+COUNTIF('Engine-FY'!B49,"FAIL")+COUNTIF('Engine-FY'!C49,"FAIL")+COUNTIF('Engine-FY'!D49,"FAIL")+COUNTIF('Engine-FY'!B53,"FAIL")+COUNTIF('Engine-FY'!C53,"FAIL")+COUNTIF('Engine-FY'!D53,"FAIL")
A4: chunk 2 | B4: =COUNTIF('Engine-FY'!B63,"FAIL")+COUNTIF('Engine-FY'!C63,"FAIL")+COUNTIF('Engine-FY'!D63,"FAIL")+COUNTIF('Engine-FY'!B68,"FAIL")+COUNTIF('Engine-FY'!C68,"FAIL")+COUNTIF('Engine-FY'!D68,"FAIL")+COUNTIF('Engine-FY'!B83,"FAIL")+COUNTIF('Engine-FY'!C83,"FAIL")+COUNTIF('Engine-FY'!D83,"FAIL")+COUNTIF('Engine'!B7,"FAIL")+COUNTIF('Engine'!C7,"FAIL")+COUNTIF('Engine'!D7,"FAIL")+COUNTIF('Engine'!E7,"FAIL")+COUNTIF('Engine'!F7,"FAIL")+COUNTIF('Engine'!G7,"FAIL")+COUNTIF('Engine'!B11,"FAIL")+COUNTIF('Engine'!C11,"FAIL")+COUNTIF('Engine'!D11,"FAIL")+COUNTIF('Engine'!E11,"FAIL")+COUNTIF('Engine'!F11,"FAIL")+COUNTIF('Engine'!G11,"FAIL")+COUNTIF('Engine'!B20,"FAIL")+COUNTIF('Engine'!C20,"FAIL")+COUNTIF('Engine'!D20,"FAIL")+COUNTIF('Engine'!E20,"FAIL")+COUNTIF('Engine'!F20,"FAIL")+COUNTIF('Engine'!G20,"FAIL")+COUNTIF('Engine'!B21,"FAIL")
A5: chunk 3 | B5: =COUNTIF('Engine'!C21,"FAIL")+COUNTIF('Engine'!D21,"FAIL")+COUNTIF('Engine'!E21,"FAIL")+COUNTIF('Engine'!F21,"FAIL")+COUNTIF('Engine'!G21,"FAIL")+COUNTIF('Engine'!B34,"FAIL")+COUNTIF('Engine'!C34,"FAIL")+COUNTIF('Engine'!D34,"FAIL")+COUNTIF('Engine'!E34,"FAIL")+COUNTIF('Engine'!F34,"FAIL")+COUNTIF('Engine'!G34,"FAIL")+COUNTIF('Engine'!B38,"FAIL")+COUNTIF('Engine'!C38,"FAIL")+COUNTIF('Engine'!D38,"FAIL")+COUNTIF('Engine'!E38,"FAIL")+COUNTIF('Engine'!F38,"FAIL")+COUNTIF('Engine'!G38,"FAIL")+COUNTIF('Engine'!B40,"FAIL")+COUNTIF('Engine'!C40,"FAIL")+COUNTIF('Engine'!D40,"FAIL")+COUNTIF('Engine'!E40,"FAIL")+COUNTIF('Engine'!F40,"FAIL")+COUNTIF('Engine'!G40,"FAIL")+COUNTIF('Engine'!B59,"FAIL")+COUNTIF('Engine'!C59,"FAIL")+COUNTIF('Engine'!D59,"FAIL")+COUNTIF('Engine'!E59,"FAIL")+COUNTIF('Engine'!F59,"FAIL")+COUNTIF('Engine'!G59,"FAIL")
A6: chunk 4 | B6: =COUNTIF('Engine'!B63,"FAIL")+COUNTIF('Engine'!B64,"FAIL")+COUNTIF('Engine'!B65,"FAIL")
A8: 87 check cells tracked. BNT engine.
