Workbook

Sheet Engine
A1: ATHENE — THE QUARTERLY ENGINE (stock & flow, every line from footed extracts)
A2: $ in millions. Blue = filed value (ATH financial supplements, sha in acquisition/manifest.csv). Black bold = formula. "check" rows show FAIL if an identity breaks. Yellow column = fill when 2Q26 publishes.
B4: 4Q24 | C4: 1Q25 | D4: 2Q25 | E4: 3Q25 | F4: 4Q25 | G4: 1Q26 | H4: 2Q26
A6: MONEY IN — BY CHANNEL
A7: Retail | B7: 7954 | C7: 9482 | D7: 7256 | E7: 10046 | F7: 7343 | G7: 7270
A8: Flow reinsurance | B8: 1029 | C8: 4933 | D8: 2031 | E8: 2542 | F8: 1665 | G8: 2603
A9: Funding agreements | B9: 5167 | C9: 11144 | D9: 11707 | E9: 9724 | F9: 2800 | G9: 8531
A10: Pension group annuities | B10: 47 | C10: 4 | D10: 1 | E10: 0 | F10: 746 | G10: 0
A11: Other spread products | B11: 0 | C11: 0 | D11: 237 | E11: 304 | F11: 133 | G11: 1343
A12: = Gross organic inflows | B12: =SUM(B7:B11) | C12: =SUM(C7:C11) | D12: =SUM(D7:D11) | E12: =SUM(E7:E11) | F12: =SUM(F7:F11) | G12: =SUM(G7:G11)
A13: Gross inorganic (block) inflows | B13: 0 | C13: 0 | D13: 0 | E13: 0 | F13: 1340 | G13: 0
A14: = TOTAL GROSS INFLOWS | B14: =B12+B13 | C14: =C12+C13 | D14: =D12+D13 | E14: =E12+E13 | F14: =F12+F13 | G14: =G12+G13
A15: reported total (filed) | B15: 14197 | C15: 25563 | D15: 21232 | E15: 22616 | F15: 14027 | G15: 19747
A16: check | B16: =IF(B14=B15,"OK","FAIL") | C16: =IF(C14=C15,"OK","FAIL") | D16: =IF(D14=D15,"OK","FAIL") | E16: =IF(E14=E15,"OK","FAIL") | F16: =IF(F14=F15,"OK","FAIL") | G16: =IF(G14=G15,"OK","FAIL")
A18: SAME MONEY, BY OWNER — the two cuts must agree
A19: Inflows attributable to Athene | B19: 8948 | C19: 20118 | D19: 15838 | E19: 17138 | F19: 10142 | G19: 15957
A20: Inflows attributable to ADIP (sidecar investors) | B20: 4343 | C20: 4956 | D20: 5019 | E20: 4962 | F20: 3515 | G20: 3453
A21: Inflows ceded to third-party reinsurers | B21: 906 | C21: 489 | D21: 375 | E21: 516 | F21: 370 | G21: 337
A22: = Total by owner | B22: =SUM(B19:B21) | C22: =SUM(C19:C21) | D22: =SUM(D19:D21) | E22: =SUM(E19:E21) | F22: =SUM(F19:F21) | G22: =SUM(G19:G21)
A23: check vs channel cut | B23: =IF(B22=B15,"OK","FAIL") | C23: =IF(C22=C15,"OK","FAIL") | D23: =IF(D22=D15,"OK","FAIL") | E23: =IF(E22=E15,"OK","FAIL") | F23: =IF(F22=F15,"OK","FAIL") | G23: =IF(G22=G15,"OK","FAIL")
A25: MONEY OUT
A26: Outflows attributable to Athene | B26: -5697 | C26: -7017 | D26: -5813 | E26: -9181 | F26: -7714 | G26: -8612
A27: Outflows attributable to ADIP | B27: -1439 | C27: -1375 | D27: -1417 | E27: -1457 | F27: -1554 | G27: -2156
A28: = Total gross outflows | B28: =B26+B27 | C28: =C26+C27 | D28: =D26+D27 | E28: =E26+E27 | F28: =F26+F27 | G28: =G26+G27
A29: reported total (filed) | B29: -7136 | C29: -8392 | D29: -7230 | E29: -10638 | F29: -9268 | G29: -10768
A30: check | B30: =IF(B28=B29,"OK","FAIL") | C30: =IF(C28=C29,"OK","FAIL") | D30: =IF(D28=D29,"OK","FAIL") | E30: =IF(E28=E29,"OK","FAIL") | F30: =IF(F28=F29,"OK","FAIL") | G30: =IF(G28=G29,"OK","FAIL")
A31: Athene outflows by type:
A32: Maturity-driven / contractual | B32: -2167 | C32: -3535 | D32: -2389 | E32: -5525 | F32: -3641 | G32: -4960
A33: Policyholder-driven | B33: -3530 | C33: -3482 | D33: -3424 | E33: -3656 | F33: -4073 | G33: -3652
A34: income-oriented (planned) | B34: -1661 | C34: -1680 | D34: -1609 | E34: -1660 | F34: -1922 | G34: -1845
A35: out of surrender charge (planned) | B35: -1131 | C35: -1058 | D35: -1025 | E35: -1093 | F35: -1198 | G35: -1089
A36: in surrender charge (unplanned) | B36: -738 | C36: -744 | D36: -790 | E36: -903 | F36: -953 | G36: -718
A37: check: policyholder = its three parts | B37: =IF(B33=SUM(B34:B36),"OK","FAIL") | C37: =IF(C33=SUM(C34:C36),"OK","FAIL") | D37: =IF(D33=SUM(D34:D36),"OK","FAIL") | E37: =IF(E33=SUM(E34:E36),"OK","FAIL") | F37: =IF(F33=SUM(F34:F36),"OK","FAIL") | G37: =IF(G33=SUM(G34:G36),"OK","FAIL")
A38: check: maturity + policyholder = Athene outflows | B38: =IF(B32+B33=B26,"OK","FAIL") | C38: =IF(C32+C33=C26,"OK","FAIL") | D38: =IF(D32+D33=D26,"OK","FAIL") | E38: =IF(E32+E33=E26,"OK","FAIL") | F38: =IF(F32+F33=F26,"OK","FAIL") | G38: =IF(G32+G33=G26,"OK","FAIL")
A40: NET FLOWS
A41: = Net flows (inflows + outflows) | B41: =B14+B28 | C41: =C14+C28 | D41: =D14+D28 | E41: =E14+E28 | F41: =F14+F28 | G41: =G14+G28
A42: reported net flows (filed) | B42: 7061 | C42: 17171 | D42: 14002 | E42: 11978 | F42: 4759 | G42: 8979
A43: check | B43: =IF(B41=B42,"OK","FAIL") | C43: =IF(C41=C42,"OK","FAIL") | D43: =IF(D41=D42,"OK","FAIL") | E43: =IF(E41=E42,"OK","FAIL") | F43: =IF(F41=F42,"OK","FAIL") | G43: =IF(G41=G42,"OK","FAIL")
A45: RESERVES — STOCK & FLOW (net reserve liabilities)
A46: Reserves — beginning | B46: 225899 | C46: 225926 | D46: 241666 | E46: 254572 | F46: 266451 | G46: 271233
...

Sheet Engine-FY
A1: ATHENE — THE ANNUAL ENGINE (same rows; FY2023 from 10-K, FY2024/25 from Q4 supplement YTD, cross-gated)
A2: Blue = filed value (ahl-10k-fy2025 MD&A + ATH Q4'25 supplement full-year columns; both sources agree exactly where they overlap). "FY25 Σq" = live sum over the Engine tab — its check must read OK. Blank FY2023 cells = row published only in supplements (older ones are glyph-encoded; decoder parked); their checks read n/a.
B4: FY2023 | C4: FY2024 | D4: FY2025 | E4: FY25 Σq | F4: src-check
A6: MONEY IN — BY CHANNEL
A7: Retail | B7: 35293 | C7: 35764 | D7: 34127 | E7: =SUM(Engine!C7:F7) | F7: =IF(D7="","n/a",IF(E7=D7,"OK","FAIL"))
A8: Flow reinsurance | B8: 10547 | C8: 5573 | D8: 11171 | E8: =SUM(Engine!C8:F8) | F8: =IF(D8="","n/a",IF(E8=D8,"OK","FAIL"))
A9: Funding agreements | B9: 7193 | C9: 28748 | D9: 35375 | E9: =SUM(Engine!C9:F9) | F9: =IF(D9="","n/a",IF(E9=D9,"OK","FAIL"))
A10: Pension group annuities | B10: 10374 | C10: 918 | D10: 751 | E10: =SUM(Engine!C10:F10) | F10: =IF(D10="","n/a",IF(E10=D10,"OK","FAIL"))
A11: Other spread products | B11: 0 | C11: 0 | D11: 674 | E11: =SUM(Engine!C11:F11) | F11: =IF(D11="","n/a",IF(E11=D11,"OK","FAIL"))
A12: = Gross organic inflows | B12: =SUM(B7:B11) | C12: =SUM(C7:C11) | D12: =SUM(D7:D11)
A13: Gross inorganic (block) inflows | B13: 2214 | C13: 0 | D13: 1340 | E13: =SUM(Engine!C13:F13) | F13: =IF(D13="","n/a",IF(E13=D13,"OK","FAIL"))
A14: = TOTAL GROSS INFLOWS | B14: =B12+B13 | C14: =C12+C13 | D14: =D12+D13
A15: reported total (filed) | B15: 65621 | C15: 71003 | D15: 83438 | E15: =SUM(Engine!C15:F15) | F15: =IF(D15="","n/a",IF(E15=D15,"OK","FAIL"))
A16: check | B16: =IF(B15="","n/a",IF(B14=B15,"OK","FAIL")) | C16: =IF(C15="","n/a",IF(C14=C15,"OK","FAIL")) | D16: =IF(D15="","n/a",IF(D14=D15,"OK","FAIL"))
A18: SAME MONEY, BY OWNER — the two cuts must agree
A19: Inflows attributable to Athene | B19: 43000 | C19: 49084 | D19: 63236 | E19: =SUM(Engine!C19:F19) | F19: =IF(D19="","n/a",IF(E19=D19,"OK","FAIL"))
A20: Inflows attributable to ADIP (sidecar investors) | B20: 22621 | C20: 17848 | D20: 18452 | E20: =SUM(Engine!C20:F20) | F20: =IF(D20="","n/a",IF(E20=D20,"OK","FAIL"))
A21: Inflows ceded to third-party reinsurers | B21: 0 | C21: 4071 | D21: 1750 | E21: =SUM(Engine!C21:F21) | F21: =IF(D21="","n/a",IF(E21=D21,"OK","FAIL"))
A22: = Total by owner | B22: =SUM(B19:B21) | C22: =SUM(C19:C21) | D22: =SUM(D19:D21)
A23: check vs channel cut | B23: =IF(B15="","n/a",IF(B22=B15,"OK","FAIL")) | C23: =IF(C15="","n/a",IF(C22=C15,"OK","FAIL")) | D23: =IF(D15="","n/a",IF(D22=D15,"OK","FAIL"))
A25: MONEY OUT
A26: Outflows attributable to Athene | B26: -28763 | C26: -27248 | D26: -29725 | E26: =SUM(Engine!C26:F26) | F26: =IF(D26="","n/a",IF(E26=D26,"OK","FAIL"))
A27: Outflows attributable to ADIP | B27: -5105 | C27: -6221 | D27: -5803 | E27: =SUM(Engine!C27:F27) | F27: =IF(D27="","n/a",IF(E27=D27,"OK","FAIL"))
A28: = Total gross outflows | B28: =B26+B27 | C28: =C26+C27 | D28: =D26+D27
A29: reported total (filed) | B29: -33868 | C29: -33469 | D29: -35528 | E29: =SUM(Engine!C29:F29) | F29: =IF(D29="","n/a",IF(E29=D29,"OK","FAIL"))
A30: check | B30: =IF(B29="","n/a",IF(B28=B29,"OK","FAIL")) | C30: =IF(C29="","n/a",IF(C28=C29,"OK","FAIL")) | D30: =IF(D29="","n/a",IF(D28=D29,"OK","FAIL"))
A31: Athene outflows by type:
A32: Maturity-driven / contractual | C32: -12096 | D32: -15090 | E32: =SUM(Engine!C32:F32) | F32: =IF(D32="","n/a",IF(E32=D32,"OK","FAIL"))
A33: Policyholder-driven | C33: -15152 | D33: -14635 | E33: =SUM(Engine!C33:F33) | F33: =IF(D33="","n/a",IF(E33=D33,"OK","FAIL"))
A34: income-oriented (planned) | C34: -6427 | D34: -6871 | E34: =SUM(Engine!C34:F34) | F34: =IF(D34="","n/a",IF(E34=D34,"OK","FAIL"))
A35: out of surrender charge (planned) | C35: -5598 | D35: -4374 | E35: =SUM(Engine!C35:F35) | F35: =IF(D35="","n/a",IF(E35=D35,"OK","FAIL"))
A36: in surrender charge (unplanned) | C36: -3127 | D36: -3390 | E36: =SUM(Engine!C36:F36) | F36: =IF(D36="","n/a",IF(E36=D36,"OK","FAIL"))
A37: check: policyholder = its three parts | B37: =IF(B36="","n/a",IF(B33=SUM(B34:B36),"OK","FAIL")) | C37: =IF(C36="","n/a",IF(C33=SUM(C34:C36),"OK","FAIL")) | D37: =IF(D36="","n/a",IF(D33=SUM(D34:D36),"OK","FAIL"))
A38: check: maturity + policyholder = Athene outflows | B38: =IF(B26="","n/a",IF(B32+B33=B26,"OK","FAIL")) | C38: =IF(C26="","n/a",IF(C32+C33=C26,"OK","FAIL")) | D38: =IF(D26="","n/a",IF(D32+D33=D26,"OK","FAIL"))
A40: NET FLOWS
A41: = Net flows (inflows + outflows) | B41: =B14+B28 | C41: =C14+C28 | D41: =D14+D28
A42: reported net flows (filed) | B42: 31753 | C42: 37534 | D42: 47910 | E42: =SUM(Engine!C42:F42) | F42: =IF(D42="","n/a",IF(E42=D42,"OK","FAIL"))
A43: check | B43: =IF(B42="","n/a",IF(B41=B42,"OK","FAIL")) | C43: =IF(C42="","n/a",IF(C41=C42,"OK","FAIL")) | D43: =IF(D42="","n/a",IF(D41=D42,"OK","FAIL"))
A45: RESERVES — STOCK & FLOW (net reserve liabilities)
A46: Reserves — beginning | C46: 199289 | D46: 225926 | E46: =SUM(Engine!C46:F46) | F46: =IF(D46="","n/a",IF(E46=D46,"OK","FAIL"))
...

Sheet Checks
A1: LIVE CHECKS — this cell must read 0
A3: Number of failing identity checks across Engine + Engine-FY: | B3: =COUNTIF('Engine'!B16,"FAIL")+COUNTIF('Engine'!C16,"FAIL")+COUNTIF('Engine'!D16,"FAIL")+COUNTIF('Engine'!E16,"FAIL")+COUNTIF('Engine'!F16,"FAIL")+COUNTIF('Engine'!G16,"FAIL")+COUNTIF('Engine'!B23,"FAIL")+COUNTIF('Engine'!C23,"FAIL")+COUNTIF('Engine'!D23,"FAIL")+COUNTIF('Engine'!E23,"FAIL")+COUNTIF('Engine'!F23,"FAIL")+COUNTIF('Engine'!G23,"FAIL")+COUNTIF('Engine'!B30,"FAIL")+COUNTIF('Engine'!C30,"FAIL")+COUNTIF('Engine'!D30,"FAIL")+COUNTIF('Engine'!E30,"FAIL")+COUNTIF('Engine'!F30,"FAIL")+COUNTIF('Engine'!G30,"FAIL")+COUNTIF('Engine'!B37,"FAIL")+COUNTIF('Engine'!C37,"FAIL")+COUNTIF('Engine'!D37,"FAIL")+COUNTIF('Engine'!E37,"FAIL")+COUNTIF('Engine'!F37,"FAIL")+COUNTIF('Engine'!G37,"FAIL")+COUNTIF('Engine'!B38,"FAIL")+COUNTIF('Engine'!C38,"FAIL")+COUNTIF('Engine'!D38,"FAIL")+COUNTIF('Engine'!E38,"FAIL")+COUNTIF('Engine'!F38,"FAIL")+COUNTIF('Engine'!G38,"FAIL")+COUNTIF('Engine'!B43,"FAIL")+COUNTIF('Engine'!C43,"FAIL")+COUNTIF('Engine'!D43,"FAIL")+COUNTIF('Engine'!E43,"FAIL")+COUNTIF('Engine'!F43,"FAIL")+COUNTIF('Engine'!G43,"FAIL")+COUNTIF('Engine'!B53,"FAIL")+COUNTIF('Engine'!C53,"FAIL")+COUNTIF('Engine'!D53,"FAIL")+COUNTIF('Engine'!E53,"FAIL")+COUNTIF('Engine'!F53,"FAIL")+COUNTIF('Engine'!G53,"FAIL")+COUNTIF('Engine'!C54,"FAIL")+COUNTIF('Engine'!D54,"FAIL")+COUNTIF('Engine'!E54,"FAIL")+COUNTIF('Engine'!F54,"FAIL")+COUNTIF('Engine'!G54,"FAIL")+COUNTIF('Engine'!B64,"FAIL")+COUNTIF('Engine'!C64,"FAIL")+COUNTIF('Engine'!D64,"FAIL")+COUNTIF('Engine'!E64,"FAIL")+COUNTIF('Engine'!F64,"FAIL")+COUNTIF('Engine'!G64,"FAIL")+COUNTIF('Engine'!B76,"FAIL")+COUNTIF('Engine'!C76,"FAIL")+COUNTIF('Engine'!D76,"FAIL")+COUNTIF('Engine'!E76,"FAIL")+COUNTIF('Engine'!F76,"FAIL")+COUNTIF('Engine'!G76,"FAIL")+COUNTIF('Engine'!B86,"FAIL")+COUNTIF('Engine'!C86,"FAIL")+COUNTIF('Engine'!D86,"FAIL")+COUNTIF('Engine'!E86,"FAIL")+COUNTIF('Engine'!F86,"FAIL")+COUNTIF('Engine'!G86,"FAIL")+COUNTIF('Engine'!B91,"FAIL")+COUNTIF('Engine'!C91,"FAIL")+COUNTIF('Engine'!D91,"FAIL")+COUNTIF('Engine'!E91,"FAIL")+COUNTIF('Engine'!F91,"FAIL")+COUNTIF('Engine'!G91,"FAIL")+COUNTIF('Engine'!B106,"FAIL")+COUNTIF('Engine'!C106,"FAIL")+COUNTIF('Engine'!D106,"FAIL")+COUNTIF('Engine'!E106,"FAIL")+COUNTIF('Engine'!F106,"FAIL")+COUNTIF('Engine'!G106,"FAIL")+COUNTIF('Engine'!B113,"FAIL")+COUNTIF('Engine'!C113,"FAIL")+COUNTIF('Engine'!D113,"FAIL")+COUNTIF('Engine'!E113,"FAIL")+COUNTIF('Engine'!F113,"FAIL")+COUNTIF('Engine'!G113,"FAIL")+COUNTIF('Engine'!B120,"FAIL")+COUNTIF('Engine'!C120,"FAIL")+COUNTIF('Engine'!D120,"FAIL")+COUNTIF('Engine'!E120,"FAIL")+COUNTIF('Engine'!F120,"FAIL")+COUNTIF('Engine'!G120,"FAIL")+COUNTIF('Engine'!B127,"FAIL")+COUNTIF('Engine'!C127,"FAIL")+COUNTIF('Engine'!D127,"FAIL")+COUNTIF('Engine'!E127,"FAIL")+COUNTIF('Engine'!F127,"FAIL")+COUNTIF('Engine'!G127,"FAIL")+COUNTIF('Engine'!B149,"FAIL")+COUNTIF('Engine'!C149,"FAIL")+COUNTIF('Engine'!D149,"FAIL")+COUNTIF('Engine'!E149,"FAIL")+COUNTIF('Engine'!F149,"FAIL")+COUNTIF('Engine'!G149,"FAIL")+COUNTIF('Engine'!B164,"FAIL")+COUNTIF('Engine'!C164,"FAIL")+COUNTIF('Engine'!D164,"FAIL")+COUNTIF('Engine'!E164,"FAIL")+COUNTIF('Engine'!F164,"FAIL")+COUNTIF('Engine'!G164,"FAIL")+COUNTIF('Engine'!B176,"FAIL")+COUNTIF('Engine'!C176,"FAIL")+COUNTIF('Engine'!D176,"FAIL")+COUNTIF('Engine'!E176,"FAIL")+COUNTIF('Engine'!F176,"FAIL")+COUNTIF('Engine'!G176,"FAIL")+COUNTIF('Engine'!B188,"FAIL")+COUNTIF('Engine'!C188,"FAIL")+COUNTIF('Engine'!D188,"FAIL")+COUNTIF('Engine'!E188,"FAIL")+COUNTIF('Engine'!F188,"FAIL")+COUNTIF('Engine'!G188,"FAIL")+COUNTIF('Engine'!B194,"FAIL")+COUNTIF('Engine'!C194,"FAIL")+COUNTIF('Engine'!D194,"FAIL")+COUNTIF('Engine'!E194,"FAIL")+COUNTIF('Engine'!F194,"FAIL")+COUNTIF('Engine'!G194,"FAIL")+COUNTIF('Engine'!B202,"FAIL")+COUNTIF('Engine'!C202,"FAIL")+COUNTIF('Engine'!D202,"FAIL")+COUNTIF('Engine'!E202,"FAIL")+COUNTIF('Engine'!F202,"FAIL")+COUNTIF('Engine'!G202,"FAIL")+COUNTIF('Engine'!B206,"FAIL")+COUNTIF('Engine'!C206,"FAIL")+COUNTIF('Engine'!D206,"FAIL")+COUNTIF('Engine'!E206,"FAIL")+COUNTIF('Engine'!F206,"FAIL")+COUNTIF('Engine'!G206,"FAIL")+COUNTIF('Engine-FY'!F7,"FAIL")+COUNTIF('Engine-FY'!F8,"FAIL")+COUNTIF('Engine-FY'!F9,"FAIL")+COUNTIF('Engine-FY'!F10,"FAIL")+COUNTIF('Engine-FY'!F11,"FAIL")+COUNTIF('Engine-FY'!F13,"FAIL")+COUNTIF('Engine-FY'!F15,"FAIL")+COUNTIF('Engine-FY'!B16,"FAIL")+COUNTIF('Engine-FY'!C16,"FAIL")+COUNTIF('Engine-FY'!D16,"FAIL")+COUNTIF('Engine-FY'!F19,"FAIL")+COUNTIF('Engine-FY'!F20,"FAIL")+COUNTIF('Engine-FY'!F21,"FAIL")+COUNTIF('Engine-FY'!B23,"FAIL")+COUNTIF('Engine-FY'!C23,"FAIL")+COUNTIF('Engine-FY'!D23,"FAIL")+COUNTIF('Engine-FY'!F26,"FAIL")+COUNTIF('Engine-FY'!F27,"FAIL")+COUNTIF('Engine-FY'!F29,"FAIL")+COUNTIF('Engine-FY'!B30,"FAIL")+COUNTIF('Engine-FY'!C30,"FAIL")+COUNTIF('Engine-FY'!D30,"FAIL")+COUNTIF('Engine-FY'!F32,"FAIL")+COUNTIF('Engine-FY'!F33,"FAIL")+COUNTIF('Engine-FY'!F34,"FAIL")+COUNTIF('Engine-FY'!F35,"FAIL")+COUNTIF('Engine-FY'!F36,"FAIL")+COUNTIF('Engine-FY'!B37,"FAIL")+COUNTIF('Engine-FY'!C37,"FAIL")+COUNTIF('Engine-FY'!D37,"FAIL")+COUNTIF('Engine-FY'!B38,"FAIL")+COUNTIF('Engine-FY'!C38,"FAIL")+COUNTIF('Engine-FY'!D38,"FAIL")+COUNTIF('Engine-FY'!F42,"FAIL")+COUNTIF('Engine-FY'!B43,"FAIL")+COUNTIF('Engine-FY'!C43,"FAIL")+COUNTIF('Engine-FY'!D43,"FAIL")+COUNTIF('Engine-FY'!F46,"FAIL")+COUNTIF('Engine-FY'!F47,"FAIL")+COUNTIF('Engine-FY'!F48,"FAIL")+COUNTIF('Engine-FY'!F49,"FAIL")+COUNTIF('Engine-FY'!F50,"FAIL")+COUNTIF('Engine-FY'!F52,"FAIL")+COUNTIF('Engine-FY'!B53,"FAIL")+COUNTIF('Engine-FY'!C53,"FAIL")+COUNTIF('Engine-FY'!D53,"FAIL")+COUNTIF('Engine-FY'!C54,"FAIL")+COUNTIF('Engine-FY'!D54,"FAIL")+COUNTIF('Engine-FY'!F57,"FAIL")+COUNTIF('Engine-FY'!F58,"FAIL")+COUNTIF('Engine-FY'!F59,"FAIL")+COUNTIF('Engine-FY'!F60,"FAIL")+COUNTIF('Engine-FY'!F61,"FAIL")+COUNTIF('Engine-FY'!F63,"FAIL")+COUNTIF('Engine-FY'!B64,"FAIL")+COUNTIF('Engine-FY'!C64,"FAIL")+COUNTIF('Engine-FY'!D64,"FAIL")+COUNTIF('Engine-FY'!F67,"FAIL")+COUNTIF('Engine-FY'!F68,"FAIL")+COUNTIF('Engine-FY'!F70,"FAIL")+COUNTIF('Engine-FY'!F71,"FAIL")+COUNTIF('Engine-FY'!F72,"FAIL")+COUNTIF('Engine-FY'!F73,"FAIL")+COUNTIF('Engine-FY'!F75,"FAIL")+COUNTIF('Engine-FY'!B76,"FAIL")+COUNTIF('Engine-FY'!C76,"FAIL")+COUNTIF('Engine-FY'!D76,"FAIL")+COUNTIF('Engine-FY'!F79,"FAIL")+COUNTIF('Engine-FY'!F80,"FAIL")+COUNTIF('Engine-FY'!F82,"FAIL")+COUNTIF('Engine-FY'!F83,"FAIL")+COUNTIF('Engine-FY'!F85,"FAIL")+COUNTIF('Engine-FY'!B86,"FAIL")+COUNTIF('Engine-FY'!C86,"FAIL")+COUNTIF('Engine-FY'!D86,"FAIL")+COUNTIF('Engine-FY'!F87,"FAIL")+COUNTIF('Engine-FY'!F88,"FAIL")+COUNTIF('Engine-FY'!F90,"FAIL")+COUNTIF('Engine-FY'!B91,"FAIL")+COUNTIF('Engine-FY'!C91,"FAIL")+COUNTIF('Engine-FY'!D91,"FAIL")+COUNTIF('Engine-FY'!F102,"FAIL")+COUNTIF('Engine-FY'!F103,"FAIL")+COUNTIF('Engine-FY'!B106,"FAIL")+COUNTIF('Engine-FY'!C106,"FAIL")+COUNTIF('Engine-FY'!D106,"FAIL")+COUNTIF('Engine-FY'!F109,"FAIL")+COUNTIF('Engine-FY'!F110,"FAIL")+COUNTIF('Engine-FY'!F111,"FAIL")+COUNTIF('Engine-FY'!F112,"FAIL")+COUNTIF('Engine-FY'!B113,"FAIL")+COUNTIF('Engine-FY'!C113,"FAIL")+COUNTIF('Engine-FY'!D113,"FAIL")+COUNTIF('Engine-FY'!F114,"FAIL")+COUNTIF('Engine-FY'!F115,"FAIL")+COUNTIF('Engine-FY'!F116,"FAIL")+COUNTIF('Engine-FY'!F117,"FAIL")+COUNTIF('Engine-FY'!F118,"FAIL")+COUNTIF('Engine-FY'!F119,"FAIL")+COUNTIF('Engine-FY'!B120,"FAIL")+COUNTIF('Engine-FY'!C120,"FAIL")+COUNTIF('Engine-FY'!D120,"FAIL")+COUNTIF('Engine-FY'!F122,"FAIL")+COUNTIF('Engine-FY'!F123,"FAIL")+COUNTIF('Engine-FY'!F124,"FAIL")+COUNTIF('Engine-FY'!B127,"FAIL")+COUNTIF('Engine-FY'!C127,"FAIL")+COUNTIF('Engine-FY'!D127,"FAIL")+COUNTIF('Engine-FY'!F130,"FAIL")+COUNTIF('Engine-FY'!F131,"FAIL")+COUNTIF('Engine-FY'!F133,"FAIL")+COUNTIF('Engine-FY'!F134,"FAIL")+COUNTIF('Engine-FY'!F135,"FAIL")+COUNTIF('Engine-FY'!F136,"FAIL")+COUNTIF('Engine-FY'!F138,"FAIL")+COUNTIF('Engine-FY'!F139,"FAIL")+COUNTIF('Engine-FY'!F140,"FAIL")+COUNTIF('Engine-FY'!F141,"FAIL")+COUNTIF('Engine-FY'!F142,"FAIL")+COUNTIF('Engine-FY'!F143,"FAIL")+COUNTIF('Engine-FY'!F145,"FAIL")+COUNTIF('Engine-FY'!F146,"FAIL")+COUNTIF('Engine-FY'!F148,"FAIL")+COUNTIF('Engine-FY'!B149,"FAIL")+COUNTIF('Engine-FY'!C149,"FAIL")+COUNTIF('Engine-FY'!D149,"FAIL")+COUNTIF('Engine-FY'!F152,"FAIL")+COUNTIF('Engine-FY'!F153,"FAIL")+COUNTIF('Engine-FY'!F154,"FAIL")+COUNTIF('Engine-FY'!F156,"FAIL")+COUNTIF('Engine-FY'!F157,"FAIL")+COUNTIF('Engine-FY'!F158,"FAIL")+COUNTIF('Engine-FY'!F159,"FAIL")+COUNTIF('Engine-FY'!F160,"FAIL")+COUNTIF('Engine-FY'!F163,"FAIL")+COUNTIF('Engine-FY'!B164,"FAIL")+COUNTIF('Engine-FY'!C164,"FAIL")+COUNTIF('Engine-FY'!D164,"FAIL")+COUNTIF('Engine-FY'!F167,"FAIL")+COUNTIF('Engine-FY'!F168,"FAIL")+COUNTIF('Engine-FY'!F169,"FAIL")+COUNTIF('Engine-FY'!F170,"FAIL")+COUNTIF('Engine-FY'!F171,"FAIL")+COUNTIF('Engine-FY'!F172,"FAIL")+COUNTIF('Engine-FY'!F173,"FAIL")+COUNTIF('Engine-FY'!F175,"FAIL")+COUNTIF('Engine-FY'!B176,"FAIL")+COUNTIF('Engine-FY'!C176,"FAIL")+COUNTIF('Engine-FY'!D176,"FAIL")+COUNTIF('Engine-FY'!F177,"FAIL")+COUNTIF('Engine-FY'!F178,"FAIL")+COUNTIF('Engine-FY'!F179,"FAIL")+COUNTIF('Engine-FY'!F180,"FAIL")+COUNTIF('Engine-FY'!F181,"FAIL")+COUNTIF('Engine-FY'!F183,"FAIL")+COUNTIF('Engine-FY'!F185,"FAIL")+COUNTIF('Engine-FY'!F187,"FAIL")+COUNTIF('Engine-FY'!B188,"FAIL")+COUNTIF('Engine-FY'!C188,"FAIL")+COUNTIF('Engine-FY'!D188,"FAIL")+COUNTIF('Engine-FY'!F189,"FAIL")+COUNTIF('Engine-FY'!F190,"FAIL")+COUNTIF('Engine-FY'!F191,"FAIL")+COUNTIF('Engine-FY'!F193,"FAIL")+COUNTIF('Engine-FY'!B194,"FAIL")+COUNTIF('Engine-FY'!C194,"FAIL")+COUNTIF('Engine-FY'!D194,"FAIL")+COUNTIF('Engine-FY'!F197,"FAIL")+COUNTIF('Engine-FY'!F198,"FAIL")+COUNTIF('Engine-FY'!F199,"FAIL")+COUNTIF('Engine-FY'!F201,"FAIL")+COUNTIF('Engine-FY'!B202,"FAIL")+COUNTIF('Engine-FY'!C202,"FAIL")+COUNTIF('Engine-FY'!D202,"FAIL")+COUNTIF('Engine-FY'!F203,"FAIL")+COUNTIF('Engine-FY'!F205,"FAIL")+COUNTIF('Engine-FY'!B206,"FAIL")+COUNTIF('Engine-FY'!C206,"FAIL")+COUNTIF('Engine-FY'!D206,"FAIL")
A5: Checks watched: 316 cells — totals cross-cuts, rollforward identities, continuity, SRE chain, derived spread, and the quarterly-vs-annual source audit.

Sheet Data
A1: period | B1: metric | C1: value | D1: source
A2: 1Q25 | B2: acra_begin | C2: 72164 | D2: supplement
A3: 1Q25 | B3: acra_end | C3: 76842 | D3: supplement
A4: 1Q25 | B4: acra_inflows | C4: 5011 | D4: supplement
A5: 1Q25 | B5: acra_other | C5: 1042 | D5: supplement
A6: 1Q25 | B6: acra_own | C6: 0 | D6: supplement
A7: 1Q25 | B7: acra_withdrawals | C7: -1375 | D7: supplement
A8: 1Q25 | B8: avg_nia | C8: 255505 | D8: supplement
A9: 1Q25 | B9: avg_nia_alt | C9: 12506 | D9: supplement
A10: 1Q25 | B10: avg_nia_fi | C10: 242999 | D10: supplement
A11: 1Q25 | B11: core_outflows | C11: -7017 | D11: supplement
A12: 1Q25 | B12: flow_reins | C12: 4933 | D12: supplement
A13: 1Q25 | B13: funding_agreements | C13: 11144 | D13: supplement
... A939: FY2025 | B939: stat:cliff_2C:other | C939: 140359.7 | D939: statutory D1 (footed)

Sheet ReadMe
A1: ATHENE ENGINE WORKBOOK — README
A3: TABS: Engine = quarterly (4Q24–1Q26 + yellow 2Q26 fill column). Engine-FY = the SAME rows annually
A4: (FY2023–FY2025) with a live "FY25 Σ quarters" audit column. Checks must read 0. Data = raw extracted cells.
A6: SOURCES: ATH Q4 2025 + Q1 2026 Financial Supplements (quarterly + full-year YTD columns) and the AHL 10-K
A7: FY2025 MD&A (annual comparatives incl. FY2023). URLs + sha256 in acquisition/manifest.csv. Every blue cell
A8: was machine-extracted and passed exact cross-foot gates; the two sources were gated equal where they overlap.
A9: Extractors: tools/parse_fin_supplement.py, tools/parse_10k_annual_tables.py.
A11: LEGEND: blue = filed value · black bold = formula (recalculates in Excel) · grey = checks ("FAIL"/"n/a")
A12: · yellow = fill-in. Blank FY2023 cells: those rows are published only in supplements, and the 2023-era
A13: supplements are glyph-encoded (decoder parked). Blanks are honest gaps, not zeros.
A15: READ THE TREND: cost of funds $5,650M (FY23) → $7,702M → $10,083M (FY25), +78% in two years, while net
A16: investment earnings grew 49%; NIS margin 1.65% (1Q25) → 1.34% (1Q26); SRE margin below 1% in 1Q26.
A17: Volume is outrunning margin, and the margin is losing.
